<?xml version="1.0" encoding="UTF-8"?>
<!-- Generated by org.testng.reporters.JUnitReportReporter -->
<testsuite skipped="0" hostname="KNOLSKAPE-L102" name="testcases.Ex4PostDeletePut" tests="3" failures="0" timestamp="28 Sep 2019 06:17:50 GMT" time="2.530" errors="1">
  <testcase name="test1" time="2.307" classname="testcases.Ex4PostDeletePut">
    <error type="junit.framework.AssertionFailedError" message="Not expected expected:&lt;201&gt; but was:&lt;500&gt;">
      <![CDATA[junit.framework.AssertionFailedError: Not expected expected:<201> but was:<500>
	at junit.framework.Assert.fail(Assert.java:47)
	at junit.framework.Assert.failNotEquals(Assert.java:282)
	at junit.framework.Assert.assertEquals(Assert.java:64)
	at junit.framework.Assert.assertEquals(Assert.java:201)
	at testcases.Ex4PostDeletePut.test1(Ex4PostDeletePut.java:28)
	at sun.reflect.NativeMethodAccessorImpl.invoke0(Native Method)
	at sun.reflect.NativeMethodAccessorImpl.invoke(NativeMethodAccessorImpl.java:62)
	at sun.reflect.DelegatingMethodAccessorImpl.invoke(DelegatingMethodAccessorImpl.java:43)
	at java.lang.reflect.Method.invoke(Method.java:498)
	at org.testng.internal.MethodInvocationHelper.invokeMethod(MethodInvocationHelper.java:108)
	at org.testng.internal.Invoker.invokeMethod(Invoker.java:661)
	at org.testng.internal.Invoker.invokeTestMethod(Invoker.java:869)
	at org.testng.internal.Invoker.invokeTestMethods(Invoker.java:1193)
	at org.testng.internal.TestMethodWorker.invokeTestMethods(TestMethodWorker.java:126)
	at org.testng.internal.TestMethodWorker.run(TestMethodWorker.java:109)
	at org.testng.TestRunner.privateRun(TestRunner.java:744)
	at org.testng.TestRunner.run(TestRunner.java:602)
	at org.testng.SuiteRunner.runTest(SuiteRunner.java:380)
	at org.testng.SuiteRunner.runSequentially(SuiteRunner.java:375)
	at org.testng.SuiteRunner.privateRun(SuiteRunner.java:340)
	at org.testng.SuiteRunner.run(SuiteRunner.java:289)
	at org.testng.SuiteRunnerWorker.runSuite(SuiteRunnerWorker.java:52)
	at org.testng.SuiteRunnerWorker.run(SuiteRunnerWorker.java:86)
	at org.testng.TestNG.runSuitesSequentially(TestNG.java:1301)
	at org.testng.TestNG.runSuitesLocally(TestNG.java:1226)
	at org.testng.TestNG.runSuites(TestNG.java:1144)
	at org.testng.TestNG.run(TestNG.java:1115)
	at org.testng.remote.AbstractRemoteTestNG.run(AbstractRemoteTestNG.java:132)
	at org.testng.remote.RemoteTestNG.initAndRun(RemoteTestNG.java:230)
	at org.testng.remote.RemoteTestNG.main(RemoteTestNG.java:76)
]]>
    </error>
  </testcase> <!-- test1 -->
  <testcase name="test2" time="0.140" classname="testcases.Ex4PostDeletePut"/>
  <testcase name="test3" time="0.083" classname="testcases.Ex4PostDeletePut"/>
</testsuite> <!-- testcases.Ex4PostDeletePut -->
